Workbook

Sheet PARAMETROS
A1: PARÁMETROS DEL SISTEMA — FinPago S.A.S. (PSPCP)
A2: Normativa base: Res. UIF N° 200/2024 | Res. UIF N° 3/2026 | BCRA Com. A 7462/2022 · Datos ficticios — Fines educativos
A4: TABLA 1 — Política de actualización del legajo KYC por nivel de riesgo
A5: NIVEL_RIESGO | B5: FRECUENCIA | C5: DÍAS_ENTRE_ACTUALIZACIONES
A6: ALTO | B6: Anual | C6: 365
A7: MEDIO | B7: Bianual | C7: 730
A8: BAJO | B8: Trianual | C8: 1095
A10: NOTA: La Res. UIF N° 200/2024 establece la obligación de Debida Diligencia Continuada y actualización del legajo según el nivel de riesgo asignado, sin fijar frecuencias universales. Las frecuencias de esta tabla son decisión de política interna del Sujeto Obligado ficticio FinPago S.A.S. y no representan un requisito normativo.
A12: TABLA 2 — Umbral de alerta de vencimiento de legajo KYC
A13: ESTADO | B13: CONDICIÓN | C13: SEMÁFORO
A14: VENCIDO | B14: Días hasta vencimiento < 0 | C14: Rojo
A15: CRÍTICO | B15: 0 ≤ Días hasta vencimiento < 30 | C15: Rojo
A16: PRÓXIMO | B16: 30 ≤ Días hasta vencimiento < 180 | C16: Amarillo
A17: AL DÍA | B17: Días hasta vencimiento ≥ 180 | C17: Verde
A19: TABLA 3 — Plazos de reportes sistemáticos obligatorios (Res. UIF N° 200/2024)
A20: TIPO_REPORTE | B20: APLICA A FINPAGO | C20: PERIODICIDAD | D20: PLAZO
A21: RSA — Reporte Sistemático Anual | B21: Sí | C21: Anual | D21: 2 de enero al 15 de marzo de cada año
A22: RTE — Reporte de Transacciones con Efectivo | B22: Sí | C22: Mensual | D22: Día 15 del mes siguiente al reportado
A23: RMTC — Reporte mensual Tarjetas de Crédito | B23: No aplica | C23: — | D23: —

Sheet CLIENTES_KYC
A1: ID_CLIENTE | B1: TIPO_PERSONA | C1: SECTOR_ACTIVIDAD | D1: NIVEL_RIESGO_FINAL | E1: DILIGENCIA_APLICABLE | F1: FECHA_ALTA_CLIENTE | G1: FECHA_ULTIMO_KYC | H1: DIAS_ENTRE_ACTUALIZACIONES | I1: FECHA_PROX_VENCIMIENTO | J1: DIAS_HASTA_VENCIMIENTO | K1: ESTADO_VENCIMIENTO | L1: COLOR_SEMAFORO | M1: DOCUMENTOS_PENDIENTES | N1: PERFIL_TRANSACCIONAL_ACTIVO | O1: COTEJO_LISTAS_ULTIMO | P1: COTEJO_LISTAS_RESULTADO | Q1: ALERTA_ACTIVA | R1: TIPO_ALERTA_ACTIVA | S1: PRIORIDAD_REVISION | T1: ANALISTA_RESPONSABLE | U1: OBSERVACIONES
A2: CLI-P1-001 | B2: Jurídica | C2: Importación/Exportación | D2: ALTO | E2: Reforzada | F2: 44630 | G2: 45945 | H2: =VLOOKUP(D2,PARAMETROS!$A$6:$C$8,3,FALSE()) -> 365 | I2: =G2+H2 -> 46310 | J2: =I2-TODAY() -> 211 | K2: =IF(J2<0,"VENCIDO",IF(J2<30,"CRÍTICO",IF(J2<180,"PRÓXIMO","AL DÍA"))) -> AL DÍA | L2: ● | M2: Ninguno | N2: Sí | O2: 46073 | P2: Sin coincidencia | Q2: Sí | R2: Volumen inusual de transacciones | S2: =IF(AND(D2="ALTO",OR(K2="VENCIDO",K2="CRÍTICO")),"URGENTE",IF(D2="ALTO","ALTA",IF(OR(K2="VENCIDO",K2="CRÍTICO"),"ALTA","NORMAL"))) -> ALTA | T2: Martín Aguirre | U2: Monitoreo activo. Patrón transaccional elevado en dic-2025 bajo análisis.
A3: CLI-P1-002 | B3: Jurídica | C3: Construcción | D3: ALTO | E3: Reforzada | F3: 44727 | G3: 45992 | H3: =VLOOKUP(D3,PARAMETROS!$A$6:$C$8,3,FALSE()) -> 365 | I3: =G3+H3 -> 46357 | J3: =I3-TODAY() -> 258 | K3: =IF(J3<0,"VENCIDO",IF(J3<30,"CRÍTICO",IF(J3<180,"PRÓXIMO","AL DÍA"))) -> AL DÍA | L3: ● | M3: Ninguno | N3: Sí | O3: 46091 | P3: Sin coincidencia | Q3: No | S3: =IF(AND(D3="ALTO",OR(K3="VENCIDO",K3="CRÍTICO")),"URGENTE",IF(D3="ALTO","ALTA",IF(OR(K3="VENCIDO",K3="CRÍTICO"),"ALTA","NORMAL"))) -> ALTA | T3: Lucía Morales
A4: CLI-P1-003 | B4: Física | C4: Tecnología | D4: ALTO | E4: Reforzada | F4: 44946 | G4: 45818 | H4: =VLOOKUP(D4,PARAMETROS!$A$6:$C$8,3,FALSE()) -> 365 | I4: =G4+H4 -> 46183 | J4: =I4-TODAY() -> 84 | K4: =IF(J4<0,"VENCIDO",IF(J4<30,"CRÍTICO",IF(J4<180,"PRÓXIMO","AL DÍA"))) -> PRÓXIMO | L4: ● | M4: Declaración de ingresos | N4: Sí | O4: 46081 | P4: Sin coincidencia | Q4: Sí | R4: Inconsistencia con perfil transaccional | S4: =IF(AND(D4="ALTO",OR(K4="VENCIDO",K4="CRÍTICO")),"URGENTE",IF(D4="ALTO","ALTA",IF(OR(K4="VENCIDO",K4="CRÍTICO"),"ALTA","NORMAL"))) -> ALTA | T4: Diego Pérez | U4: Documentación pendiente. Notificar al cliente 30 días antes del vencimiento.
A5: CLI-P1-004 | B5: Jurídica | C5: Servicios profesionales | D5: ALTO | E5: Reforzada | F5: 44870 | G5: 45863 | H5: =VLOOKUP(D5,PARAMETROS!$A$6:$C$8,3,FALSE()) -> 365 | I5: =G5+H5 -> 46228 | J5: =I5-TODAY() -> 129 | K5: =IF(J5<0,"VENCIDO",IF(J5<30,"CRÍTICO",IF(J5<180,"PRÓXIMO","AL DÍA"))) -> PRÓXIMO | L5: ● | M5: Ninguno | N5: Sí | O5: 46086 | P5: Sin coincidencia | Q5: No | S5: =IF(AND(D5="ALTO",OR(K5="VENCIDO",K5="CRÍTICO")),"URGENTE",IF(D5="ALTO","ALTA",IF(OR(K5="VENCIDO",K5="CRÍTICO"),"ALTA","NORMAL"))) -> ALTA | T5: Martín Aguirre
A6: CLI-P1-005 | B6: Jurídica | C6: Importación/Exportación | D6: ALTO | E6: Reforzada | F6: 44576 | G6: 45736 | H6: =VLOOKUP(D6,PARAMETROS!$A$6:$C$8,3,FALSE()) -> 365 | I6: =G6+H6 -> 46101 | J6: =I6-TODAY() -> 2 | K6: =IF(J6<0,"VENCIDO",IF(J6<30,"CRÍTICO",IF(J6<180,"PRÓXIMO","AL DÍA"))) -> CRÍTICO | L6: ● | M6: Origen de fondos | N6: En revisión | O6: 46068 | P6: Coincidencia parcial | Q6: Sí | R6: Cotejo FPADM con resultado pendiente | S6: =IF(AND(D6="ALTO",OR(K6="VENCIDO",K6="CRÍTICO")),"URGENTE",IF(D6="ALTO","ALTA",IF(OR(K6="VENCIDO",K6="CRÍTICO"),"ALTA","NORMAL"))) -> URGENTE | T6: Ana González | U6: URGENTE: Vencimiento inminente. Coincidencia parcial FPADM sin resolver. Escalar a Oficial de Cumplimiento.
A7: CLI-P1-006 | B7: Física | C7: Construcción | D7: ALTO | E7: Reforzada | F7: 45026 | G7: 45744 | H7: =VLOOKUP(D7,PARAMETROS!$A$6:$C$8,3,FALSE()) -> 365 | I7: =G7+H7 -> 46109 | J7: =I7-TODAY() -> 10 | K7: =IF(J7<0,"VENCIDO",IF(J7<30,"CRÍTICO",IF(J7<180,"PRÓXIMO","AL DÍA"))) -> CRÍTICO | L7: ● | M7: DNI actualizado | N7: Sí | O7: 46073 | P7: Sin coincidencia | Q7: Sí | R7: Legajo KYC próximo a vencer | S7: =IF(AND(D7="ALTO",OR(K7="VENCIDO",K7="CRÍTICO")),"URGENTE",IF(D7="ALTO","ALTA",IF(OR(K7="VENCIDO",K7="CRÍTICO"),"ALTA","NORMAL"))) -> URGENTE | T7: Martín Aguirre | U7: URGENTE: DNI desactualizado. Contactar cliente para renovación presencial.
A8: CLI-P1-007 | B8: Jurídica | C8: Transporte | D8: ALTO | E8: Reforzada | F8: 44793 | G8: 45748 | H8: =VLOOKUP(D8,PARAMETROS!$A$6:$C$8,3,FALSE()) -> 365 | I8: =G8+H8 -> 46113 | J8: =I8-TODAY() -> 14 | K8: =IF(J8<0,"VENCIDO",IF(J8<30,"CRÍTICO",IF(J8<180,"PRÓXIMO","AL DÍA"))) -> CRÍTICO | L8: ● | M8: Ninguno | N8: Sí | O8: 46082 | P8: Sin coincidencia | Q8: Sí | R8: Origen de fondos no justificado | S8: =IF(AND(D8="ALTO",OR(K8="VENCIDO",K8="CRÍTICO")),"URGENTE",IF(D8="ALTO","ALTA",IF(OR(K8="VENCIDO",K8="CRÍTICO"),"ALTA","NORMAL"))) -> URGENTE | T8: Lucía Morales | U8: URGENTE: Investigación origen de fondos en curso. Solicitar documentación adicional.
A9: CLI-P1-008 | B9: Jurídica | C9: Tecnología | D9: ALTO | E9: Reforzada | F9: 44958 | G9: 45755 | H9: =VLOOKUP(D9,PARAMETROS!$A$6:$C$8,3,FALSE()) -> 365 | I9: =G9+H9 -> 46120 | J9: =I9-TODAY() -> 21 | K9: =IF(J9<0,"VENCIDO",IF(J9<30,"CRÍTICO",IF(J9<180,"PRÓXIMO","AL DÍA"))) -> CRÍTICO | L9: ● | M9: Declaración de ingresos | N9: En revisión | O9: 46063 | P9: Sin coincidencia | Q9: Sí | R9: Fraccionamiento sospechoso | S9: =IF(AND(D9="ALTO",OR(K9="VENCIDO",K9="CRÍTICO")),"URGENTE",IF(D9="ALTO","ALTA",IF(OR(K9="VENCIDO",K9="CRÍTICO"),"ALTA","NORMAL"))) -> URGENTE | T9: Diego Pérez | U9: URGENTE: Análisis de fraccionamiento en curso. Documentación incompleta.
A10: CLI-P1-009 | B10: Física | C10: Servicios profesionales | D10: ALTO | E10: Reforzada | F10: 44691 | G10: 45636 | H10: =VLOOKUP(D10,PARAMETROS!$A$6:$C$8,3,FALSE()) -> 365 | I10: =G10+H10 -> 46001 | J10: =I10-TODAY() -> -98 | K10: =IF(J10<0,"VENCIDO",IF(J10<30,"CRÍTICO",IF(J10<180,"PRÓXIMO","AL DÍA"))) -> VENCIDO | L10: ● | M10: Origen de fondos | N10: No | O10: 46006 | P10: Coincidencia parcial | Q10: Sí | R10: Legajo KYC vencido | S10: =IF(AND(D10="ALTO",OR(K10="VENCIDO",K10="CRÍTICO")),"URGENTE",IF(D10="ALTO","ALTA",IF(OR(K10="VENCIDO",K10="CRÍTICO"),"ALTA","NORMAL"))) -> URGENTE | T10: Ana González | U10: URGENTE: Legajo VENCIDO. Coincidencia parcial FPADM activa. Suspensión de operaciones evaluada por Oficial.
A11: CLI-P1-010 | B11: Jurídica | C11: Agropecuario | D11: ALTO | E11: Reforzada | F11: 44440 | G11: 45555 | H11: =VLOOKUP(D11,PARAMETROS!$A$6:$C$8,3,FALSE()) -> 365 | I11: =G11+H11 -> 45920 | J11: =I11-TODAY() -> -179 | K11: =IF(J11<0,"VENCIDO",IF(J11<30,"CRÍTICO",IF(J11<180,"PRÓXIMO","AL DÍA"))) -> VENCIDO | L11: ● | M11: Estatuto actualizado | N11: No | O11: 45925 | P11: Sin coincidencia | Q11: Sí | R11: Legajo KYC vencido | S11: =IF(AND(D11="ALTO",OR(K11="VENCIDO",K11="CRÍTICO")),"URGENTE",IF(D11="ALTO","ALTA",IF(OR(K11="VENCIDO",K11="CRÍTICO"),"ALTA","NORMAL"))) -> URGENTE | T11: Martín Aguirre | U11: URGENTE: Legajo VENCIDO. Estatuto social vencido. Operaciones suspendidas hasta renovación.
A12: CLI-P1-011 | B12: Física | C12: Comercio electrónico | D12: MEDIO | E12: Estándar | F12: 44743 | G12: 45555 | H12: =VLOOKUP(D12,PARAMETROS!$A$6:$C$8,3,FALSE()) -> 730 | I12: =G12+H12 -> 46285 | J12: =I12-TODAY() -> 186 | K12: =IF(J12<0,"VENCIDO",IF(J12<30,"CRÍTICO",IF(J12<180,"PRÓXIMO","AL DÍA"))) -> AL DÍA | L12: ● | M12: Ninguno | N12: Sí | O12: 46091 | P12: Sin coincidencia | Q12: No | S12: =IF(AND(D12="ALTO",OR(K12="VENCIDO",K12="CRÍTICO")),"URGENTE",IF(D12="ALTO","ALTA",IF(OR(K12="VENCIDO",K12="CRÍTICO"),"ALTA","NORMAL"))) -> NORMAL | T12: Lucía Morales
A13: CLI-P1-012 | B13: Jurídica | C13: Gastronomía | D13: MEDIO | E13: Estándar | F13: 44666 | G13: 45566 | H13: =VLOOKUP(D13,PARAMETROS!$A$6:$C$8,3,FALSE()) -> 730 | I13: =G13+H13 -> 46296 | J13: =I13-TODAY() -> 197 | K13: =IF(J13<0,"VENCIDO",IF(J13<30,"CRÍTICO",IF(J13<180,"PRÓXIMO","AL DÍA"))) -> AL DÍA | L13: ● | M13: Ninguno | N13: Sí | O13: 46078 | P13: Sin coincidencia | Q13: No | S13: =IF(AND(D13="ALTO",OR(K13="VENCIDO",K13="CRÍTICO")),"URGENTE",IF(D13="ALTO","ALTA",IF(OR(K13="VENCIDO",K13="CRÍTICO"),"ALTA","NORMAL"))) -> NORMAL | T13: Diego Pérez
A14: CLI-P1-013 | B14: Física | C14: Salud | D14: MEDIO | E14: Estándar | F14: 44986 | G14: 45585 | H14: =VLOOKUP(D14,PARAMETROS!$A$6:$C$8,3,FALSE()) -> 730 | I14: =G14+H14 -> 46315 | J14: =I14-TODAY() -> 216 | K14: =IF(J14<0,"VENCIDO",IF(J14<30,"CRÍTICO",IF(J14<180,"PRÓXIMO","AL DÍA"))) -> AL DÍA | L14: ● | M14: Ninguno | N14: Sí | O14: 46086 | P14: Sin coincidencia | Q14: No | S14: =IF(AND(D14="ALTO",OR(K14="VENCIDO",K14="CRÍTICO")),"URGENTE",IF(D14="ALTO","ALTA",IF(OR(K14="VENCIDO",K14="CRÍTICO"),"ALTA","NORMAL"))) -> NORMAL | T14: Ana González
A15: CLI-P1-014 | B15: Jurídica | C15: Educación | D15: MEDIO | E15: Estándar | F15: 44814 | G15: 45601 | H15: =VLOOKUP(D15,PARAMETROS!$A$6:$C$8,3,FALSE()) -> 730 | I15: =G15+H15 -> 46331 | J15: =I15-TODAY() -> 232 | K15: =IF(J15<0,"VENCIDO",IF(J15<30,"CRÍTICO",IF(J15<180,"PRÓXIMO","AL DÍA"))) -> AL DÍA | L15: ● | M15: Ninguno | N15: Sí | O15: 46082 | P15: Sin coincidencia | Q15: No | S15: =IF(AND(D15="ALTO",OR(K15="VENCIDO",K15="CRÍTICO")),"URGENTE",IF(D15="ALTO","ALTA",IF(OR(K15="VENCIDO",K15="CRÍTICO"),"ALTA","NORMAL"))) -> NORMAL | T15: Martín Aguirre
A16: CLI-P1-015 | B16: Física | C16: Tecnología | D16: MEDIO | E16: Estándar | F16: 45097 | G16: 45616 | H16: =VLOOKUP(D16,PARAMETROS!$A$6:$C$8,3,FALSE()) -> 730 | I16: =G16+H16 -> 46346 | J16: =I16-TODAY() -> 247 | K16: =IF(J16<0,"VENCIDO",IF(J16<30,"CRÍTICO",IF(J16<180,"PRÓXIMO","AL DÍA"))) -> AL DÍA | L16: ● | M16: Ninguno | N16: Sí | O16: 46091 | P16: Sin coincidencia | Q16: No | S16: =IF(AND(D16="ALTO",OR(K16="VENCIDO",K16="CRÍTICO")),"URGENTE",IF(D16="ALTO","ALTA",IF(OR(K16="VENCIDO",K16="CRÍTICO"),"ALTA","NORMAL"))) -> NORMAL | T16: Lucía Morales
A17: CLI-P1-016 | B17: Jurídica | C17: Comercio electrónico | D17: MEDIO | E17: Estándar | F17: 44896 | G17: 45636 | H17: =VLOOKUP(D17,PARAMETROS!$A$6:$C$8,3,FALSE()) -> 730 | I17: =G17+H17 -> 46366 | J17: =I17-TODAY() -> 267 | K17: =IF(J17<0,"VENCIDO",IF(J17<30,"CRÍTICO",IF(J17<180,"PRÓXIMO","AL DÍA"))) -> AL DÍA | L17: ● | M17: Ninguno | N17: Sí | O17: 46073 | P17: Sin coincidencia | Q17: No | S17: =IF(AND(D17="ALTO",OR(K17="VENCIDO",K17="CRÍTICO")),"URGENTE",IF(D17="ALTO","ALTA",IF(OR(K17="VENCIDO",K17="CRÍTICO"),"ALTA","NORMAL"))) -> NORMAL | T17: Diego Pérez
A18: CLI-P1-017 | B18: Física | C18: Agropecuario | D18: MEDIO | E18: Estándar | F18: 44931 | G18: 45672 | H18: =VLOOKUP(D18,PARAMETROS!$A$6:$C$8,3,FALSE()) -> 730 | I18: =G18+H18 -> 46402 | J18: =I18-TODAY() -> 303 | K18: =IF(J18<0,"VENCIDO",IF(J18<30,"CRÍTICO",IF(J18<180,"PRÓXIMO","AL DÍA"))) -> AL DÍA | L18: ● | M18: Ninguno | N18: Sí | O18: 46091 | P18: Sin coincidencia | Q18: No | S18: =IF(AND(D18="ALTO",OR(K18="VENCIDO",K18="CRÍTICO")),"URGENTE",IF(D18="ALTO","ALTA",IF(OR(K18="VENCIDO",K18="CRÍTICO"),"ALTA","NORMAL"))) -> NORMAL | T18: Ana González
A19: CLI-P1-018 | B19: Jurídica | C19: Transporte | D19: MEDIO | E19: Estándar | F19: 44788 | G19: 45698 | H19: =VLOOKUP(D19,PARAMETROS!$A$6:$C$8,3,FALSE()) -> 730 | I19: =G19+H19 -> 46428 | J19: =I19-TODAY() -> 329 | K19: =IF(J19<0,"VENCIDO",IF(J19<30,"CRÍTICO",IF(J19<180,"PRÓXIMO","AL DÍA"))) -> AL DÍA | L19: ● | M19: Ninguno | N19: Sí | O19: 46086 | P19: Sin coincidencia | Q19: No | S19: =IF(AND(D19="ALTO",OR(K19="VENCIDO",K19="CRÍTICO")),"URGENTE",IF(D19="ALTO","ALTA",IF(OR(K19="VENCIDO",K19="CRÍTICO"),"ALTA","NORMAL"))) -> NORMAL | T19: Martín Aguirre
A20: CLI-P1-019 | B20: Física | C20: Construcción | D20: MEDIO | E20: Estándar | F20: 45117 | G20: 45741 | H20: =VLOOKUP(D20,PARAMETROS!$A$6:$C$8,3,FALSE()) -> 730 | I20: =G20+H20 -> 46471 | J20: =I20-TODAY() -> 372 | K20: =IF(J20<0,"VENCIDO",IF(J20<30,"CRÍTICO",IF(J20<180,"PRÓXIMO","AL DÍA"))) -> AL DÍA | L20: ● | M20: Ninguno | N20: Sí | O20: 46091 | P20: Sin coincidencia | Q20: No | S20: =IF(AND(D20="ALTO",OR(K20="VENCIDO",K20="CRÍTICO")),"URGENTE",IF(D20="ALTO","ALTA",IF(OR(K20="VENCIDO",K20="CRÍTICO"),"ALTA","NORMAL"))) -> NORMAL | T20: Lucía Morales
A21: CLI-P1-020 | B21: Jurídica | C21: Servicios profesionales | D21: MEDIO | E21: Estándar | F21: 45174 | G21: 45792 | H21: =VLOOKUP(D21,PARAMETROS!$A$6:$C$8,3,FALSE()) -> 730 | I21: =G21+H21 -> 46522 | J21: =I21-TODAY() -> 423 | K21: =IF(J21<0,"VENCIDO",IF(J21<30,"CRÍTICO",IF(J21<180,"PRÓXIMO","AL DÍA"))) -> AL DÍA | L21: ● | M21: Ninguno | N21: Sí | O21: 46081 | P21: Sin coincidencia | Q21: No | S21: =IF(AND(D21="ALTO",OR(K21="VENCIDO",K21="CRÍTICO")),"URGENTE",IF(D21="ALTO","ALTA",IF(OR(K21="VENCIDO",K21="CRÍTICO"),"ALTA","NORMAL"))) -> NORMAL | T21: Diego Pérez
A22: CLI-P1-021 | B22: Física | C22: Salud | D22: MEDIO | E22: Estándar | F22: 45301 | G22: 45839 | H22: =VLOOKUP(D22,PARAMETROS!$A$6:$C$8,3,FALSE()) -> 730 | I22: =G22+H22 -> 46569 | J22: =I22-TODAY() -> 470 | K22: =IF(J22<0,"VENCIDO",IF(J22<30,"CRÍTICO",IF(J22<180,"PRÓXIMO","AL DÍA"))) -> AL DÍA | L22: ● | M22: Ninguno | N22: Sí | O22: 46082 | P22: Sin coincidencia | Q22: No | S22: =IF(AND(D22="ALTO",OR(K22="VENCIDO",K22="CRÍTICO")),"URGENTE",IF(D22="ALTO","ALTA",IF(OR(K22="VENCIDO",K22="CRÍTICO"),"ALTA","NORMAL"))) -> NORMAL | T22: Ana González
A23: CLI-P1-022 | B23: Jurídica | C23: Importación/Exportación | D23: MEDIO | E23: Estándar | F23: 45250 | G23: 45910 | H23: =VLOOKUP(D23,PARAMETROS!$A$6:$C$8,3,FALSE()) -> 730 | I23: =G23+H23 -> 46640 | J23: =I23-TODAY() -> 541 | K23: =IF(J23<0,"VENCIDO",IF(J23<30,"CRÍTICO",IF(J23<180,"PRÓXIMO","AL DÍA"))) -> AL DÍA | L23: ● | M23: Ninguno | N23: Sí | O23: 46086 | P23: Sin coincidencia | Q23: No | S23: =IF(AND(D23="ALTO",OR(K23="VENCIDO",K23="CRÍTICO")),"URGENTE",IF(D23="ALTO","ALTA",IF(OR(K23="VENCIDO",K23="CRÍTICO"),"ALTA","NORMAL"))) -> NORMAL | T23: Martín Aguirre
A24: CLI-P1-023 | B24: Física | C24: Comercio electrónico | D24: MEDIO | E24: Estándar | F24: 44576 | G24: 45422 | H24: =VLOOKUP(D24,PARAMETROS!$A$6:$C$8,3,FALSE()) -> 730 | I24: =G24+H24 -> 46152 | J24: =I24-TODAY() -> 53 | K24: =IF(J24<0,"VENCIDO",IF(J24<30,"CRÍTICO",IF(J24<180,"PRÓXIMO","AL DÍA"))) -> PRÓXIMO | L24: ● | M24: Declaración de ingresos | N24: Sí | O24: 46042 | P24: Sin coincidencia | Q24: Sí | R24: Inconsistencia con perfil transaccional | S24: =IF(AND(D24="ALTO",OR(K24="VENCIDO",K24="CRÍTICO")),"URGENTE",IF(D24="ALTO","ALTA",IF(OR(K24="VENCIDO",K24="CRÍTICO"),"ALTA","NORMAL"))) -> NORMAL | T24: Lucía Morales | U24: Vencimiento próximo. Declaración de ingresos pendiente de renovación.
A25: CLI-P1-024 | B25: Jurídica | C25: Gastronomía | D25: MEDIO | E25: Estándar | F25: 44640 | G25: 45440 | H25: =VLOOKUP(D25,PARAMETROS!$A$6:$C$8,3,FALSE()) -> 730 | I25: =G25+H25 -> 46170 | J25: =I25-TODAY() -> 71 | K25: =IF(J25<0,"VENCIDO",IF(J25<30,"CRÍTICO",IF(J25<180,"PRÓXIMO","AL DÍA"))) -> PRÓXIMO | L25: ● | M25: Ninguno | N25: Sí | O25: 46063 | P25: Sin coincidencia | Q25: No | S25: =IF(AND(D25="ALTO",OR(K25="VENCIDO",K25="CRÍTICO")),"URGENTE",IF(D25="ALTO","ALTA",IF(OR(K25="VENCIDO",K25="CRÍTICO"),"ALTA","NORMAL"))) -> NORMAL | T25: Diego Pérez | U25: Programar notificación de renovación KYC.
A26: CLI-P1-025 | B26: Física | C26: Educación | D26: MEDIO | E26: Estándar | F26: 44722 | G26: 45458 | H26: =VLOOKUP(D26,PARAMETROS!$A$6:$C$8,3,FALSE()) -> 730 | I26: =G26+H26 -> 46188 | J26: =I26-TODAY() -> 89 | K26: =IF(J26<0,"VENCIDO",IF(J26<30,"CRÍTICO",IF(J26<180,"PRÓXIMO","AL DÍA"))) -> PRÓXIMO | L26: ● | M26: DNI actualizado | N26: Sí | O26: 46037 | P26: Sin coincidencia | Q26: No | S26: =IF(AND(D26="ALTO",OR(K26="VENCIDO",K26="CRÍTICO")),"URGENTE",IF(D26="ALTO","ALTA",IF(OR(K26="VENCIDO",K26="CRÍTICO"),"ALTA","NORMAL"))) -> NORMAL | T26: Ana González
A27: CLI-P1-026 | B27: Jurídica | C27: Tecnología | D27: MEDIO | E27: Estándar | F27: 44774 | G27: 45474 | H27: =VLOOKUP(D27,PARAMETROS!$A$6:$C$8,3,FALSE()) -> 730 | I27: =G27+H27 -> 46204 | J27: =I27-TODAY() -> 105 | K27: =IF(J27<0,"VENCIDO",IF(J27<30,"CRÍTICO",IF(J27<180,"PRÓXIMO","AL DÍA"))) -> PRÓXIMO | L27: ● | M27: Ninguno | N27: Sí | O27: 46073 | P27: Sin coincidencia | Q27: No | S27: =IF(AND(D27="ALTO",OR(K27="VENCIDO",K27="CRÍTICO")),"URGENTE",IF(D27="ALTO","ALTA",IF(OR(K27="VENCIDO",K27="CRÍTICO"),"ALTA","NORMAL"))) -> NORMAL | T27: Martín Aguirre
A28: CLI-P1-027 | B28: Física | C28: Agropecuario | D28: MEDIO | E28: Estándar | F28: 44849 | G28: 45493 | H28: =VLOOKUP(D28,PARAMETROS!$A$6:$C$8,3,FALSE()) -> 730 | I28: =G28+H28 -> 46223 | J28: =I28-TODAY() -> 124 | K28: =IF(J28<0,"VENCIDO",IF(J28<30,"CRÍTICO",IF(J28<180,"PRÓXIMO","AL DÍA"))) -> PRÓXIMO | L28: ● | M28: Ninguno | N28: Sí | O28: 46068 | P28: Sin coincidencia | Q28: No | S28: =IF(AND(D28="ALTO",OR(K28="VENCIDO",K28="CRÍTICO")),"URGENTE",IF(D28="ALTO","ALTA",IF(OR(K28="VENCIDO",K28="CRÍTICO"),"ALTA","NORMAL"))) -> NORMAL | T28: Lucía Morales
A29: CLI-P1-028 | B29: Jurídica | C29: Transporte | D29: MEDIO | E29: Estándar | F29: 44900 | G29: 45509 | H29: =VLOOKUP(D29,PARAMETROS!$A$6:$C$8,3,FALSE()) -> 730 | I29: =G29+H29 -> 46239 | J29: =I29-TODAY() -> 140 | K29: =IF(J29<0,"VENCIDO",IF(J29<30,"CRÍTICO",IF(J29<180,"PRÓXIMO","AL DÍA"))) -> PRÓXIMO | L29: ● | M29: Ninguno | N29: Sí | O29: 46086 | P29: Sin coincidencia | Q29: No | S29: =IF(AND(D29="ALTO",OR(K29="VENCIDO",K29="CRÍTICO")),"URGENTE",IF(D29="ALTO","ALTA",IF(OR(K29="VENCIDO",K29="CRÍTICO"),"ALTA","NORMAL"))) -> NORMAL | T29: Diego Pérez
A30: CLI-P1-029 | B30: Física | C30: Construcción | D30: MEDIO | E30: Estándar | F30: 44510 | G30: 45383 | H30: =VLOOKUP(D30,PARAMETROS!$A$6:$C$8,3,FALSE()) -> 730 | I30: =G30+H30 -> 46113 | J30: =I30-TODAY() -> 14 | K30: =IF(J30<0,"VENCIDO",IF(J30<30,"CRÍTICO",IF(J30<180,"PRÓXIMO","AL DÍA"))) -> CRÍTICO | L30: ● | M30: Origen de fondos | N30: En revisión | O30: 46001 | P30: Sin coincidencia | Q30: Sí | R30: Origen de fondos no justificado | S30: =IF(AND(D30="ALTO",OR(K30="VENCIDO",K30="CRÍTICO")),"URGENTE",IF(D30="ALTO","ALTA",IF(OR(K30="VENCIDO",K30="CRÍTICO"),"ALTA","NORMAL"))) -> ALTA | T30: Ana González | U30: ALTA PRIORIDAD: Vencimiento inminente. Origen de fondos pendiente. Iniciar renovación.
A31: CLI-P1-030 | B31: Jurídica | C31: Servicios profesionales | D31: MEDIO | E31: Estándar | F31: 44352 | G31: 45250 | H31: =VLOOKUP(D31,PARAMETROS!$A$6:$C$8,3,FALSE()) -> 730 | I31: =G31+H31 -> 45980 | J31: =I31-TODAY() -> -119 | K31: =IF(J31<0,"VENCIDO",IF(J31<30,"CRÍTICO",IF(J31<180,"PRÓXIMO","AL DÍA"))) -> VENCIDO | L31: ● | M31: Estatuto actualizado | N31: No | O31: 45823 | P31: Sin coincidencia | Q31: Sí | R31: Legajo KYC vencido | S31: =IF(AND(D31="ALTO",OR(K31="VENCIDO",K31="CRÍTICO")),"URGENTE",IF(D31="ALTO","ALTA",IF(OR(K31="VENCIDO",K31="CRÍTICO"),"ALTA","NORMAL"))) -> ALTA | T31: Martín Aguirre | U31: ALTA PRIORIDAD: Legajo VENCIDO. Estatuto vencido. Iniciar renovación de inmediato.
A32: CLI-P1-031 | B32: Física | C32: Comercio electrónico | D32: BAJO | E32: Simplificada | F32: 44409 | G32: 45189 | H32: =VLOOKUP(D32,PARAMETROS!$A$6:$C$8,3,FALSE()) -> 1095 | I32: =G32+H32 -> 46284 | J32: =I32-TODAY() -> 185 | K32: =IF(J32<0,"VENCIDO",IF(J32<30,"CRÍTICO",IF(J32<180,"PRÓXIMO","AL DÍA"))) -> AL DÍA | L32: ● | M32: Ninguno | N32: Sí | O32: 46091 | P32: Sin coincidencia | Q32: No | S32: =IF(AND(D32="ALTO",OR(K32="VENCIDO",K32="CRÍTICO")),"URGENTE",IF(D32="ALTO","ALTA",IF(OR(K32="VENCIDO",K32="CRÍTICO"),"ALTA","NORMAL"))) -> NORMAL | T32: Lucía Morales
A33: CLI-P1-032 | B33: Jurídica | C33: Gastronomía | D33: BAJO | E33: Simplificada | F33: 44484 | G33: 45214 | H33: =VLOOKUP(D33,PARAMETROS!$A$6:$C$8,3,FALSE()) -> 1095 | I33: =G33+H33 -> 46309 | J33: =I33-TODAY() -> 210 | K33: =IF(J33<0,"VENCIDO",IF(J33<30,"CRÍTICO",IF(J33<180,"PRÓXIMO","AL DÍA"))) -> AL DÍA | L33: ● | M33: Ninguno | N33: Sí | O33: 46073 | P33: Sin coincidencia | Q33: No | S33: =IF(AND(D33="ALTO",OR(K33="VENCIDO",K33="CRÍTICO")),"URGENTE",IF(D33="ALTO","ALTA",IF(OR(K33="VENCIDO",K33="CRÍTICO"),"ALTA","NORMAL"))) -> NORMAL | T33: Diego Pérez
A34: CLI-P1-033 | B34: Física | C34: Salud | D34: BAJO | E34: Simplificada | F34: 44612 | G34: 45231 | H34: =VLOOKUP(D34,PARAMETROS!$A$6:$C$8,3,FALSE()) -> 1095 | I34: =G34+H34 -> 46326 | J34: =I34-TODAY() -> 227 | K34: =IF(J34<0,"VENCIDO",IF(J34<30,"CRÍTICO",IF(J34<180,"PRÓXIMO","AL DÍA"))) -> AL DÍA | L34: ● | M34: Ninguno | N34: Sí | O34: 46086 | P34: Sin coincidencia | Q34: No | S34: =IF(AND(D34="ALTO",OR(K34="VENCIDO",K34="CRÍTICO")),"URGENTE",IF(D34="ALTO","ALTA",IF(OR(K34="VENCIDO",K34="CRÍTICO"),"ALTA","NORMAL"))) -> NORMAL | T34: Ana González
A35: CLI-P1-034 | B35: Jurídica | C35: Educación | D35: BAJO | E35: Simplificada | F35: 44444 | G35: 45270 | H35: =VLOOKUP(D35,PARAMETROS!$A$6:$C$8,3,FALSE()) -> 1095 | I35: =G35+H35 -> 46365 | J35: =I35-TODAY() -> 266 | K35: =IF(J35<0,"VENCIDO",IF(J35<30,"CRÍTICO",IF(J35<180,"PRÓXIMO","AL DÍA"))) -> AL DÍA | L35: ● | M35: Ninguno | N35: Sí | O35: 46081 | P35: Sin coincidencia | Q35: No | S35: =IF(AND(D35="ALTO",OR(K35="VENCIDO",K35="CRÍTICO")),"URGENTE",IF(D35="ALTO","ALTA",IF(OR(K35="VENCIDO",K35="CRÍTICO"),"ALTA","NORMAL"))) -> NORMAL | T35: Martín Aguirre
A36: CLI-P1-035 | B36: Física | C36: Tecnología | D36: BAJO | E36: Simplificada | F36: 44661 | G36: 45306 | H36: =VLOOKUP(D36,PARAMETROS!$A$6:$C$8,3,FALSE()) -> 1095 | I36: =G36+H36 -> 46401 | J36: =I36-TODAY() -> 302 | K36: =IF(J36<0,"VENCIDO",IF(J36<30,"CRÍTICO",IF(J36<180,"PRÓXIMO","AL DÍA"))) -> AL DÍA | L36: ● | M36: Ninguno | N36: Sí | O36: 46091 | P36: Sin coincidencia | Q36: No | S36: =IF(AND(D36="ALTO",OR(K36="VENCIDO",K36="CRÍTICO")),"URGENTE",IF(D36="ALTO","ALTA",IF(OR(K36="VENCIDO",K36="CRÍTICO"),"ALTA","NORMAL"))) -> NORMAL | T36: Lucía Morales
A37: CLI-P1-036 | B37: Jurídica | C37: Agropecuario | D37: BAJO | E37: Simplificada | F37: 44397 | G37: 45342 | H37: =VLOOKUP(D37,PARAMETROS!$A$6:$C$8,3,FALSE()) -> 1095 | I37: =G37+H37 -> 46437 | J37: =I37-TODAY() -> 338 | K37: =IF(J37<0,"VENCIDO",IF(J37<30,"CRÍTICO",IF(J37<180,"PRÓXIMO","AL DÍA"))) -> AL DÍA | L37: ● | M37: Ninguno | N37: Sí | O37: 46082 | P37: Sin coincidencia | Q37: No | S37: =IF(AND(D37="ALTO",OR(K37="VENCIDO",K37="CRÍTICO")),"URGENTE",IF(D37="ALTO","ALTA",IF(OR(K37="VENCIDO",K37="CRÍTICO"),"ALTA","NORMAL"))) -> NORMAL | T37: Diego Pérez
A38: CLI-P1-037 | B38: Física | C38: Transporte | D38: BAJO | E38: Simplificada | F38: 44696 | G38: 45376 | H38: =VLOOKUP(D38,PARAMETROS!$A$6:$C$8,3,FALSE()) -> 1095 | I38: =G38+H38 -> 46471 | J38: =I38-TODAY() -> 372 | K38: =IF(J38<0,"VENCIDO",IF(J38<30,"CRÍTICO",IF(J38<180,"PRÓXIMO","AL DÍA"))) -> AL DÍA | L38: ● | M38: Ninguno | N38: Sí | O38: 46078 | P38: Sin coincidencia | Q38: No | S38: =IF(AND(D38="ALTO",OR(K38="VENCIDO",K38="CRÍTICO")),"URGENTE",IF(D38="ALTO","ALTA",IF(OR(K38="VENCIDO",K38="CRÍTICO"),"ALTA","NORMAL"))) -> NORMAL | T38: Ana González
A39: CLI-P1-038 | B39: Jurídica | C39: Comercio electrónico | D39: BAJO | E39: Simplificada | F39: 44571 | G39: 45422 | H39: =VLOOKUP(D39,PARAMETROS!$A$6:$C$8,3,FALSE()) -> 1095 | I39: =G39+H39 -> 46517 | J39: =I39-TODAY() -> 418 | K39: =IF(J39<0,"VENCIDO",IF(J39<30,"CRÍTICO",IF(J39<180,"PRÓXIMO","AL DÍA"))) -> AL DÍA | L39: ● | M39: Ninguno | N39: Sí | O39: 46086 | P39: Sin coincidencia | Q39: No | S39: =IF(AND(D39="ALTO",OR(K39="VENCIDO",K39="CRÍTICO")),"URGENTE",IF(D39="ALTO","ALTA",IF(OR(K39="VENCIDO",K39="CRÍTICO"),"ALTA","NORMAL"))) -> NORMAL | T39: Martín Aguirre
A40: CLI-P1-039 | B40: Física | C40: Gastronomía | D40: BAJO | E40: Simplificada | F40: 44767 | G40: 45458 | H40: =VLOOKUP(D40,PARAMETROS!$A$6:$C$8,3,FALSE()) -> 1095 | I40: =G40+H40 -> 46553 | J40: =I40-TODAY() -> 454 | K40: =IF(J40<0,"VENCIDO",IF(J40<30,"CRÍTICO",IF(J40<180,"PRÓXIMO","AL DÍA"))) -> AL DÍA | L40: ● | M40: Ninguno | N40: Sí | O40: 46073 | P40: Sin coincidencia | Q40: No | S40: =IF(AND(D40="ALTO",OR(K40="VENCIDO",K40="CRÍTICO")),"URGENTE",IF(D40="ALTO","ALTA",IF(OR(K40="VENCIDO",K40="CRÍTICO"),"ALTA","NORMAL"))) -> NORMAL | T40: Lucía Morales
...

Sheet REPORTES_SISTEMATICOS
A1: TIPO_REPORTE | B1: PERÍODO_REPORTADO | C1: FECHA_LIMITE | D1: FECHA_PRESENTACION | E1: ESTADO | F1: DÍAS_DESVÍO | G1: OBSERVACIONES
A2: RSA — Reporte Sistemático Anual | B2: Año 2025 | C2: 46096 | D2: 46091 | E2: Presentado | F2: 5 | G2: Presentado dentro del plazo. 5 días de anticipación.
A3: RTE — Reporte de Transacciones con Efectivo | B3: Enero 2026 | C3: 46068 | D3: 46065 | E3: Presentado | F3: 3 | G3: Presentado dentro del plazo.
A4: RTE — Reporte de Transacciones con Efectivo | B4: Febrero 2026 | C4: 46096 | D4: 46094 | E4: Presentado | F4: 2 | G4: Presentado dentro del plazo.
A5: RTE — Reporte de Transacciones con Efectivo | B5: Marzo 2026 | C5: 46127 | D5: — | E5: Pendiente | F5: =C5-TODAY() -> 28 | G5: Plazo vigente. Período en curso. Vencimiento: 15/04/2026.
A8: REFERENCIA NORMATIVA (Res. UIF N° 200/2024): RSA — Reporte Sistemático Anual: presentación anual entre el 2 de enero y el 15 de marzo de cada año calendario. RTE — Reporte de Transacciones con Efectivo: presentación mensual hasta el día 15 del mes siguiente al período reportado. RMTC — Reporte mensual Tarjetas de Crédito: no aplica a PSPCPs. Primer RSA de FinPago S.A.S.: entre el 2 de enero y el 15 de marzo de 2026. DATOS FICTICIOS — Proyecto de portfolio educativo. No representan información real.

Sheet ALERTAS_ACTIVAS
A1: ID_CASO | B1: ID_CLIENTE | C1: TIPO_ALERTA | D1: FECHA_ALERTA | E1: ESTADO | F1: DÍAS_ABIERTO
A2: CAS-P5-001 | B2: CLI-P1-001 | C2: Volumen inusual de transacciones | D2: 46006 | E2: Abierto | F2: =TODAY()-D2 -> 93
A3: CAS-P5-002 | B3: CLI-P1-003 | C3: Inconsistencia con perfil transaccional | D3: 46042 | E3: Abierto | F3: =TODAY()-D3 -> 57
A4: CAS-P5-003 | B4: CLI-P1-005 | C4: Cotejo FPADM — resultado pendiente de verificación | D4: 46054 | E4: Abierto | F4: =TODAY()-D4 -> 45
A5: CAS-P5-004 | B5: CLI-P1-006 | C5: Legajo KYC próximo a vencer (cliente ALTO riesgo) | D5: 46073 | E5: Abierto | F5: =TODAY()-D5 -> 26
A6: CAS-P5-005 | B6: CLI-P1-007 | C6: Origen de fondos no justificado | D6: 45971 | E6: Abierto | F6: =TODAY()-D6 -> 128
A7: CAS-P5-006 | B7: CLI-P1-008 | C7: Fraccionamiento sospechoso de operaciones | D7: 46027 | E7: Abierto | F7: =TODAY()-D7 -> 72
A8: CAS-P5-007 | B8: CLI-P1-009 | C8: Legajo KYC vencido — cliente ALTO riesgo | D8: 45748 | E8: Abierto | F8: =TODAY()-D8 -> 351
A9: CAS-P5-008 | B9: CLI-P1-009 | C9: Coincidencia parcial en lista FPADM — en verificación | D9: 46037 | E9: Abierto | F9: =TODAY()-D9 -> 62
A10: CAS-P5-009 | B10: CLI-P1-010 | C10: Legajo KYC vencido — operaciones suspendidas | D10: 45689 | E10: Abierto | F10: =TODAY()-D10 -> 410
A11: CAS-P5-010 | B11: CLI-P1-023 | C11: Inconsistencia perfil transaccional (variación >30%) | D11: 46063 | E11: Abierto | F11: =TODAY()-D11 -> 36
A12: CAS-P5-011 | B12: CLI-P1-029 | C12: Origen de fondos no justificado — documentación incompleta | D12: 46042 | E12: Abierto | F12: =TODAY()-D12 -> 57
A13: CAS-P5-012 | B13: CLI-P1-030 | C13: Legajo KYC vencido — cliente MEDIO riesgo | D13: 45505 | E13: Abierto | F13: =TODAY()-D13 -> 594
... A16: CAS-P5-015 | B16: CLI-P1-050 | C16: Coincidencia parcial en lista FPADM — pendiente de resolución | D16: 46032 | E16: Abierto | F16: =TODAY()-D16 -> 67
